Workbook

Sheet Profiles
A1: Comparative Analysis
A3: Elite Eight Profiles | D3: Charlotte Profiles
A4: Striker | B4: 21 | C4: Difference | D4: 2 | E4: Striker
A5: Goals to xG | B5: =SUM(Clemson!F3:F5,'Oregon State'!F3,WVU!F3,'Notre Dame'!F3:F5,Stanford!F3:F6,UNC!F3,LMU!E3:E6,Indiana!E3:E6)/SUM(Clemson!G3:G5,'Oregon State'!G3,WVU!G3,'Notre Dame'!G3:G5,Stanford!G3:G6,UNC!G3,LMU!F3:F6,Indiana!F3:F6) -> 1.1271703 | C5: =D5-B5 -> -0.76745803 | D5: =(SUM(UNCC!F3:F4)/SUM(UNCC!G3:G4))/2 -> 0.35971223 | E5: Goals to xG
A6: Key Passes | B6: =SUM(Clemson!H3:H5,'Oregon State'!H3,WVU!H3,'Notre Dame'!H3:H5,Stanford!H3:H6,UNC!H3,LMU!G3:G6,Indiana!G3:G6)/21 -> 6.8571429 | C6: =D6-B6 -> -3.8571429 | D6: =SUM(UNCC!H3:H4)/2 -> 3 | E6: Key Passes
A7: Opponent Half Recoveries | B7: =SUM(Clemson!K3:K5,'Oregon State'!K3,WVU!L3,'Notre Dame'!K3:K5,31,27,7,11,32,LMU!N3:N6,43,62,32,4)/21 -> 29.380952 | C7: =D7-B7 -> -9.3809524 | D7: =SUM(29,11)/2 -> 20 | E7: Opponent Half Recoveries
A8: Elite Eight Profiles | D8: Charlotte Profiles
A9: Winger | B9: 24 | D9: 4 | E9: Winger
A10: Opponent Half Recoveries | B10: =SUM(Clemson!N8:N9,'Oregon State'!N6:N9,'Notre Dame'!N8:N10,89,67,UNC!N6:N9,LMU!M24:M25,54,82,15)/24 -> 36.041667 | C10: =D10-B10 -> -6.2916667 | D10: =SUM(UNCC!N7:N10)/4 -> 29.75 | E10: Opponent Half Recoveries
A11: Successful Dribbles (Amnt) | B11: =SUM(Clemson!F8:F9,Clemson!F11:F14,'Oregon State'!F6:F9,'Notre Dame'!F8:F10,Stanford!F9:F10,UNC!F6:F9,LMU!E24:E25,Indiana!E9:E11)/24 -> 40.375 | C11: =D11-B11 -> -10.625 | D11: =SUM(UNCC!F7:F10)/4 -> 29.75 | E11: Successful Dribbles (Amnt)
A12: Successful Dribbles (%) | B12: =SUM(Clemson!G8:G9,Clemson!G11:G14,'Oregon State'!G6:G9,'Notre Dame'!G8:G10,Stanford!G9:G10,UNC!G6:G9,LMU!F24:F25,Indiana!F9:F11)/24 -> 0.56166667 | C12: =D12-B12 -> -0.094166667 | D12: =SUM(UNCC!G7:G10)/4 -> 0.4675 | E12: Successful Dribbles (%)
A13: Accurate Crosses (Amnt) | B13: =SUM(Clemson!I8:I9,Clemson!I11:I14,'Oregon State'!I6:I9,'Notre Dame'!I8:I10,Stanford!I9:I10,UNC!I6:I9,LMU!H24:H25,Indiana!H9:H11)/24 -> 12.208333 | C13: =D13-B13 -> -0.70833333 | D13: =SUM(UNCC!I7:I10)/4 -> 11.5 | E13: Crosses (Amnt)
A14: Accurate Crosses (%) | B14: =SUM(Clemson!J8:J9,Clemson!J11:J14,'Oregon State'!J6:J9,'Notre Dame'!J8:J10,Stanford!J9:J10,UNC!J6:J9,LMU!I24:I25,Indiana!I9:I11)/24 -> 0.29916667 | C14: =D14-B14 -> 0.19833333 | D14: =SUM(UNCC!J7:J10)/4 -> 0.4975 | E14: Crosses (%)
A15: Key Passes | B15: =SUM(Clemson!L8:L9,Clemson!L11:L14,'Oregon State'!L6:L9,2,13,10,Stanford!L9:L10,UNC!L6:L9,LMU!K24:K25,Indiana!K9:K11)/24 -> 8.6666667 | C15: =D15-B15 -> 8.5833333 | D15: =SUM(UNCC!L7:L10)/4 -> 17.25 | E15: Key Passes
A16: Goals | B16: =SUM(Clemson!M8:M9,Clemson!M11:M14,'Oregon State'!M6:M9,0,2,4,Stanford!M9:M10,UNC!M6:M9,LMU!L24:L25,Indiana!L9:L11)/24 -> 3.1666667 | C16: =D16-B16 -> -0.91666667 | D16: =SUM(UNCC!M7:M10)/4 -> 2.25 | E16: Goals
A17: Elite Eight Profiles
A18: Attacking Mids | B18: 4 | D18: 0 | E18: Attacking Mids
A19: Goals | B19: =SUM(WVU!N20:N23)/4 -> 7 | D19: - | E19: Goals
A20: Key Passes | B20: =SUM(WVU!O20:O23)/4 -> 12.25 | D20: - | E20: Key Passes
A21: Opponent Half Recoveries | B21: =SUM(61,44,58,39)/4 -> 50.5 | D21: - | E21: Opponent Half Recoveries
A22: Elite Eight Profiles | D22: Charlotte Profiles
A23: Center/Def Mids | B23: 23 | D23: 4 | E23: Center/Def Mids
A24: Accurate Passes (Amnt) | B24: =SUM(Clemson!F25:F26,'Oregon State'!F25:F26,WVU!F18:F19,'Notre Dame'!F23:F25,Stanford!F23:F25,UNC!F21:F24,LMU!E18:E21,Indiana!E23:E25)/23 -> 539.26087 | C24: =D24-B24 -> -163.01087 | D24: =SUM(UNCC!F24:F27)/4 -> 376.25 | E24: Passes (Amnt)
A25: Accurate Passes (%) | B25: =SUM(Clemson!G25:G26,'Oregon State'!G25:G26,WVU!G18:G19,'Notre Dame'!G23:G25,Stanford!G23:G25,UNC!G21:G24,LMU!F18:F21,Indiana!F23:F25)/23 -> 0.81304348 | C25: =D25-B25 -> -0.053043478 | D25: =SUM(UNCC!G24:G27)/4 -> 0.76 | E25: Passes (%)
A26: Loose Ball Duels Won | B26: =SUM(Clemson!I25:I26,'Oregon State'!I25:I26,WVU!I18:I19,'Notre Dame'!I23:I25,Stanford!I23:I25,UNC!I21:I24,LMU!J18:J21,Indiana!H23:H25)/23 -> 21.826087 | C26: =D26-B26 -> -5.576087 | D26: =SUM(UNCC!I24:I27)/4 -> 16.25 | E26: Loose Ball Duels Won
A27: Progressive Passes (Amnt) | B27: =SUM(Clemson!L25:L26,'Oregon State'!L25:L26,WVU!L18:L19,'Notre Dame'!L23:L25,Stanford!L23:L25,UNC!L21:L24,LMU!J18:J21,Indiana!K23:K25)/23 -> 69.782609 | C27: =D27-B27 -> -11.782609 | D27: =SUM(UNCC!L24:L27)/4 -> 58 | E27: Progressive Passes (Amnt)
A28: Progressive Passes (%) | B28: =SUM(Clemson!M25:M26,'Oregon State'!M25:M26,WVU!M18:M19,'Notre Dame'!M23:M25,Stanford!M23:M25,UNC!M21:M24,LMU!M18:M21,Indiana!L23:L25)/23 -> 0.67782609 | C28: =D28-B28 -> 0.074673913 | D28: =SUM(UNCC!M24:M27)/4 -> 0.7525 | E28: Progressive Passes (%)
A29: Elite Eight Profiles | D29: Charlotte Profiles
A30: Center Backs | B30: 22 | D30: 2 | E30: Center Backs
A31: Accurate Passes (Amnt) | B31: =SUM(Clemson!F17:F19,'Oregon State'!F12:F15,'Notre Dame'!F13:F15,Indiana!E15:E16,WVU!F6,WVU!F8,WVU!F10,Stanford!F13,Stanford!F15,UNC!F12,UNC!F14,LMU!E10:E11)/22 -> 668.81818 | C31: =D31-B31 -> -58.318182 | D31: =SUM(UNCC!F13:F14)/2 -> 610.5 | E31: Passes (Amnt)
A32: Accurate Passes (%) | B32: =SUM(Clemson!G17:G19,'Oregon State'!G12:G15,WVU!G6,WVU!G8,WVU!G10,'Notre Dame'!G13:G15,Stanford!G13,Stanford!G15,UNC!G12,UNC!G14,LMU!F9:F11,Indiana!F15:F16)/22 -> 0.85409091 | C32: =D32-B32 -> -0.039090909 | D32: =SUM(UNCC!G13:G14)/2 -> 0.815 | E32: Passes (%)
A33: Def Duels (Amnt) | B33: =SUM(Clemson!I17:I19,'Oregon State'!I12:I15,WVU!I6,WVU!I8,WVU!I10,'Notre Dame'!I13:I15,Stanford!I13,Stanford!I15,UNC!I12,UNC!I14,LMU!J9:J11,Indiana!H15:H16)/22 -> 74.454545 | C33: =D33-B33 -> -12.954545 | D33: =SUM(UNCC!I13:I14)/2 -> 61.5 | E33: Def Duels (Amnt)
A34: Def Duels (%) | B34: =SUM(Clemson!J17:J19,'Oregon State'!J12:J15,WVU!J6,WVU!J8,WVU!J10,'Notre Dame'!J13:J15,Stanford!J13,Stanford!J15,UNC!J12,UNC!J14,LMU!M9:M11,Indiana!I15:I16)/22 -> 0.67454545 | C34: =D34-B34 -> -0.0045454545 | D34: =SUM(UNCC!J13:J14)/2 -> 0.67 | E34: Def Duels (%)
A35: Interceptions | B35: =SUM(Clemson!L17:L19,'Oregon State'!L12:L15,WVU!L6,WVU!L8,WVU!L10,'Notre Dame'!L13:L15,Stanford!L13,Stanford!L15,UNC!L12,UNC!L14,LMU!O9:O11,Indiana!K15:K16)/22 -> 91.545455 | C35: =D35-B35 -> 2.4545455 | D35: =SUM(UNCC!L13:L14)/2 -> 94 | E35: Interceptions
A36: Clearances | B36: =SUM(Clemson!M17:M19,'Oregon State'!M12:M15,WVU!M6,WVU!M8,WVU!M10,'Notre Dame'!M13:M15,Stanford!M13,Stanford!M15,UNC!M14,UNC!M12,LMU!P9:P11,Indiana!L15:L16)/22 -> 57.136364 | C36: =D36-B36 -> -14.136364 | D36: =SUM(UNCC!M13:M14)/2 -> 43 | E36: Clearances
A37: Blocked Shots | B37: =SUM(Clemson!N17:N19,'Oregon State'!N12:N15,WVU!N10,WVU!N8,WVU!N6,'Notre Dame'!N13:N15,Stanford!N13,Stanford!N15,UNC!N12,UNC!N14,LMU!Q9:Q11,Indiana!M15:M16)/22 -> 10.954545 | C37: =D37-B37 -> -2.4545455 | D37: =SUM(UNCC!N13:N14)/2 -> 8.5 | E37: Blocked Shots
A38: Elite Eight Profiles | D38: Charlotte Profiles
A39: Full Backs | B39: 22 | D39: 2 | E39: Full Backs
A40: Accurate Passes (Amnt) | B40: =SUM(Clemson!F29:F32,'Oregon State'!F18:F20,WVU!F7,WVU!F9,WVU!F11:F12,'Notre Dame'!F17:F18,Stanford!I14,Stanford!I16:I17,UNC!F13,UNC!F15:F16,LMU!E12,Indiana!E14,Indiana!E17)/22 -> 429.5 | C40: =D40-B40 -> -93.5 | D40: =SUM(UNCC!F17:F18)/2 -> 336 | E40: Passes (Amnt)
A41: Accurate Passes (%) | B41: =SUM(Clemson!G29:G32,'Oregon State'!G18:G20,WVU!J7,WVU!J9,WVU!J11:J12,'Notre Dame'!G17:G18,Stanford!G14,Stanford!G16:G17,UNC!G13,UNC!G15:G16,LMU!F12,Indiana!I14,Indiana!I17)/22 -> 0.71863636 | C41: =D41-B41 -> 0.041363636 | D41: =SUM(UNCC!G17:G18)/2 -> 0.76 | E41: Passes (%)
...

Sheet Clemson
A1: Player | B1: Position | C1: Position Category | D1: Average Minutes Played | E1: Position Metrics
E2: Goals to XG | F2: goals | G2: xg | H2: Key Passes | K2: Opp Half Recoveries
A3: O. Sylla | B3: CF | C3: Striker | D3: 90' | E3: 12/8.1 | F3: 12 | G3: 8.1 | H3: 24 | K3: 42
A4: T. Trimnal | B4: CF | C4: Striker | D4: 53' | E4: 5/4.44 | F4: 5 | G4: 4.44 | H4: 5 | K4: 25
A5: M. Seye | B5: CF | C5: Striker | D5: 42' | E5: 5/4.83 | F5: 5 | G5: 4.83 | H5: 3 | K5: 10
D6: =SUM(90,53,42) -> 185
E7: Successful Dribbles (Amount and Successful %) | F7: amnt | G7: % | H7: Crosses (Amount and Accurate %) | I7: amnt | J7: % | K7: Key Passes/Goals | L7: Key Passes | M7: Goals | N7: Opp Half Recoveries
A8: N. Richmond | B8: RWF | C8: Wingers | D8: 61' | E8: 39/72 (54%) | F8: 39 | G8: 0.54 | H8: 18/42 (43%) | I8: 18 | J8: 0.43 | K8: 17 / 5 Goals | L8: 17 | M8: 5 | N8: 35
A9: A. Meinhard | B9: LWF | C9: Wingers | D9: 91' | E9: 39/75 (52%) | F9: 39 | G9: 0.52 | H9: 9/28 (32%) | I9: 9 | J9: 0.28 | K9: 11 / 8 Goals | L9: 11 | M9: 8 | N9: 58
E10: Successful Dribbles (Amount and Successful %) | F10: amnt | G10: % | H10: Crosses (Amount and Accurate %) | I10: amnt | J10: % | K10: Key Passes/Goals | L10: Key Passes | M10: Goals | N10: Opp Half Recoveries
A11: A. Duquenne | C11: Wingers | D11: 86' | E11: 41/57 (72%) | F11: 41 | G11: 0.72 | H11: 29/88 (33%) | I11: 29 | J11: 0.33 | K11: 15 / 2 Goals | L11: 15 | M11: 2 | N11: 65
A12: S. Smart | C12: Wingers | D12: 88' | E12: 71/112 (63%) | F12: 71 | G12: 0.63 | H12: 14/67 (21%) | I12: 14 | J12: 0.21 | K12: 3 / 2 Goals | L12: 3 | M12: 2 | N12: 79
A13: R. Okunlola | C13: Wingers | D13: 44' | E13: 19/37 (51%) | F13: 19 | G13: 0.51 | H13: 13/39 (33%) | I13: 13 | J13: 0.33 | K13: 8 / 2 Goals | L13: 8 | M13: 2 | N13: 24
A14: E. Montana | C14: Wingers | D14: 35' | E14: 8/12 (67%) | F14: 8 | G14: 0.67 | H14: 12/25 (48%) | I14: 12 | J14: 0.48 | K14: 6 / 0 Goals | L14: 6 | M14: 0 | N14: 22
E16: Total Passes and Accuracy % | F16: amnt | G16: % | H16: Defensive Duels Won % | I16: amnt | J16: % | K16: Interceptions/Clearances | L16: ints | M16: clears | N16: Blocked Shots
A17: P. Mar Boye | B17: CB | C17: Center Back | D17: 105' | E17: 781/909 (86%) | F17: 781 | G17: 0.86 | H17: 115/163 (71%) | I17: 115 | J17: 0.71 | K17: 119/49 | L17: 119 | M17: 49 | N17: 10
A18: A. Lundegard | B18: LCB | C18: Center Back | D18: 99' | E18: 879/1101 (80%) | F18: 879 | G18: 0.8 | H18: 104/170 (61%) | I18: 104 | J18: 0.61 | K18: 121/41 | L18: 121 | M18: 41 | N18: 4
A19: G. Gibert | B19: RCB | C19: Center Back | D19: 104' | E19: 982/1101 (90%) | F19: 982 | G19: 0.9 | H19: 138/199 (69%) | I19: 138 | J19: 0.69 | K19: 114/48 | L19: 114 | M19: 48 | N19: 12
E21: XG to Goals Conceded | F21: xg | G21: conceded | H21: Goals Against Average | K21: Save Percentage %
A22: J. Andema | B22: GK | C22: Goalkeeper | D22: 105' | E22: 22.97/19 | F22: 22.97 | G22: 19 | H22: 0.83 | K22: 0.74
E24: Passes Amount & Accuracy % | F24: amnt | G24: % | H24: Loose Balls Duels Won | I24: amnt | J24: % | K24: Progressive Passes/ Accuracy % | L24: pps | M24: %
A25: J. Gerbet | B25: CMF | C25: Center Mid | D25: 101' | E25: 982/1078 (91%) | F25: 982 | G25: 0.91 | H25: 25/59 (42%) | I25: 25 | J25: 0.42 | K25: 130/145 (90%) | L25: 130 | M25: 0.9
A26: B. Parrish | B26: RCMF | C26: Center Mid | D26: 92' | E26: 539/703 (77%) | F26: 539 | G26: 0.77 | H26: 14/49 (29%) | I26: 14 | J26: 0.29 | K26: 99/133 (74%) | L26: 99 | M26: 0.74
E28: Total Passes and Accuracy % | F28: amnt | G28: % | H28: Defensive Duels Won % | I28: amnt | J28: % | K28: Interceptions/Clearances | L28: ints | M28: clears | N28: Crosses / Accuracy % | O28: crosses | P28: % | Q28: Success Dribbles / Success % | R28: dribbles | S28: %
A29: A. Duquenne | B29: LWB | C29: Fullbacks | D29: 86' | E29: 520/722 (72%) | F29: 520 | G29: 0.72 | H29: 98/161 (61%) | I29: 98 | J29: 0.61 | K29: 60/16 | L29: 60 | M29: 16 | N29: 29/79 (37%) | O29: 29 | P29: 0.37 | Q29: 41/57 (72%) | R29: 41 | S29: 0.72
A30: S. Smart | B30: RWB | C30: Fullbacks | D30: 88' | E30: 695/921 (75%) | F30: 695 | G30: 0.75 | H30: 138/223 (62%) | I30: 138 | J30: 0.62 | K30: 92/30 | L30: 92 | M30: 30 | N30: 14/67 (21%) | O30: 14 | P30: 0.21 | Q30: 71/112 (63%) | R30: 71 | S30: 0.63
A31: R. Okunlola | B31: RWB | C31: Fullbacks | D31: 44' | E31: 179/260 (69%) | F31: 179 | G31: 0.69 | H31: 35/54 (65%) | I31: 35 | J31: 0.65 | K31: 38/19 | L31: 38 | M31: 19 | N31: 13/39 (39%) | O31: 13 | P31: 0.39 | Q31: 19/37 (51%) | R31: 19 | S31: 0.51
A32: E. Montana | B32: LWB | C32: Fullbacks | D32: 35' | E32: 167/230 (73%) | F32: 167 | G32: 0.73 | H32: 15/22 (68%) | I32: 15 | J32: 0.68 | K32: 18/6 | L32: 18 | M32: 6 | N32: 12/25 (48%) | O32: 12 | P32: 0.48 | Q32: 8/15 (53%) | R32: 8 | S32: 0.53
B36: stkr | C36: =COUNTIF($C$2:$C$35,"Striker") -> 3
B37: winger | C37: =COUNTIF($C$2:$C$35,"Wingers") -> 6
B38: am | C38: =COUNTIF($C$2:$C$35,"Attacking Mids") -> 0
B39: cm/cdm | C39: =COUNTIF($C$2:$C$35,"Wingers") -> 6
B40: fb | C40: =COUNTIF($C$2:$C$35,"Wingers") -> 6
B41: cb | C41: =COUNTIF($C$2:$C$35,"Center Back") -> 3

Sheet Oregon State
A1: Player | B1: Position | C1: Position Category | D1: Average Minutes Played | E1: Position Metrics
E2: Goals to XG | F2: goals | G2: xg | H2: Key Passes | K2: Opp Half Recoveries
A3: L. Farrington | B3: CF | C3: Striker | D3: 91' | E3: 12/10.98 | F3: 12 | G3: 10.98 | H3: 6 | K3: 30
E5: Successful Dribbles (Amount and Successful %) | F5: amnt | G5: % | H5: Crosses (Amount and Accurate %) | K5: Key Passes/Goals | L5: kp | M5: goals | N5: Opp Half Recoveries
A6: Fran Cortijo | B6: LW | C6: Wingers | D6: 65' | E6: 4/8 (50%) | F6: 4 | G6: 0.5 | H6: 12/40 (30%) | I6: 12 | J6: 0.3 | K6: 5 / 3 Goals | L6: 5 | M6: 3 | N6: 17
A7: Vicho Castro | B7: LW | C7: Wingers | D7: 41' | E7: 24/40 (60%) | F7: 24 | G7: 0.6 | H7: 4/16 (25%) | I7: 4 | J7: 0.25 | K7: 2 / 3 Goals | L7: 2 | M7: 3 | N7: 22
A8: A. Farnos | B8: RW | C8: Wingers | D8: 94' | E8: 37/80 (46%) | F8: 37 | G8: 0.46 | H8: 8/24 (33%) | I8: 8 | J8: 0.33 | K8: 9 / 3 Goals | L8: 9 | M8: 3 | N8: 47
A9: E. Spikner | B9: RAMF | C9: Wingers | D9: 53' | E9: 37/67 (55%) | F9: 37 | G9: 0.55 | H9: 8/27 (30% | I9: 8 | J9: 0.3 | K9: 9 / 4 Goals | L9: 9 | M9: 4 | N9: 19
E11: Total Passes and Accuracy % | H11: Defensive Duels Won % | K11: Interceptions/Clearances | N11: Blocked Shots
A12: J. Armas | B12: LCB | C12: Center Back | D12: 99' | E12: 649/778 (83%) | F12: 649 | G12: 0.83 | H12: 66/108 (61%) | I12: 66 | J12: 0.61 | K12: 90/43 | L12: 90 | M12: 43 | N12: 11
A13: T. Humphrey | B13: RCB | C13: Center Back | D13: 99' | E13: 596/720 (83%) | F13: 596 | G13: 0.83 | H13: 88/116 (76%) | I13: 88 | J13: 0.76 | K13: 99/70 | L13: 99 | M13: 70 | N13: 11
A14: J. Zapien | B14: LCB | C14: Center Back | D14: 49' | E14: 221/248 (89%) | F14: 221 | G14: 0.89 | H14: 32/47 (68%) | I14: 32 | J14: 0.68 | K14: 39/8 | L14: 39 | M14: 8 | N14: 2
A15: N. Lund | B15: LCB | C15: Center Back | D15: 81' | E15: 427/488 (88%) | F15: 427 | G15: 0.88 | H15: 27/41 (66%) | I15: 27 | J15: 0.66 | K15: 38/39 | L15: 38 | M15: 39 | N15: 8
E17: Total Passes and Accuracy % | H17: Defensive Duels Won % | K17: Interceptions/Clearances
A18: E. Newman | B18: RB | C18: Fullbacks | D18: 74' | E18: 184/251 (73%) | F18: 184 | G18: 0.73 | H18: 46/73 (63%) | I18: 46 | J18: 0.63 | K18: 36/26 | L18: 36 | M18: 26
A19: A. De Gannes | B19: LB | C19: Fullbacks | D19: 64' | E19: 540/657 (82%) | F19: 540 | G19: 0.82 | H19: 66/114 (58%) | I19: 66 | J19: 0.58 | K19: 77/33 | L19: 77 | M19: 33
A20: D. Williams | B20: RB | C20: Fullbacks | D20: 83' | E20: 371/508 (73%) | F20: 371 | G20: 0.73 | H20: 92/174 (53%) | I20: 92 | J20: 0.53 | K20: 68/19 | L20: 68 | M20: 19
E21: xg to goals con | F21: xg | G21: goals con
A22: L. Castillo | B22: GK | C22: Goalkeeper | D22: 101' | E22: 29.35/24 | F22: 29.35 | G22: 24 | H22: 1.66 | K22: 0.67
E24: Passes Amount & Accuracy % | H24: Loose Balls Duels Won | K24: Progressive Passes/ Accuracy %
A25: P. Belmonte | B25: LCMF | C25: Center Mid | D25: 93' | E25: 537/611 (88%) | F25: 537 | G25: 0.88 | H25: 14/18 (77%) | I25: 14 | J25: 0.77 | K25: 45/65 (69%) | L25: 45 | M25: 0.69
A26: T. Bedouret | B26: RCMF | C26: Center Mid | D26: 57' | E26: 404/465 (87%) | F26: 404 | G26: 0.87 | H26: 19/39 (49%) | I26: 19 | J26: 0.49 | K26: 59/73 (81%) | L26: 59 | M26: 0.81
C29: =COUNTIF($C$2:$C$26,"Center Back") -> 4

Sheet WVU
A1: Player | B1: Position | C1: Position Category | D1: Average Minutes Played | E1: Position Metrics
E2: Goals to XG | H2: Key Passes | K2: Opp Half Recoveries
A3: M. Caldeira | B3: CF | C3: Striker | D3: 87' | E3: 12/9.06 | F3: 12 | G3: 9.06 | H3: 11 | K3: 58/67 (87%) | L3: 58
E5: Total Passes and Accuracy % | H5: Defensive Duels Won % | K5: Interceptions/Clearances | N5: Blocked Shots
A6: M. Broughton | B6: RCB | C6: Center Back | D6: 32' | E6: 1228/1372 (90%) | F6: 1228 | G6: 0.9 | H6: 55/87 (63%) | I6: 55 | J6: 0.63 | K6: 101/87 | L6: 101 | M6: 87 | N6: 15
A7: F. Jorgensen | B7: LB | C7: Full Back | D7: 54' | E7: 945/1112 (85%) | F7: 945 | G7: 0.85 | H7: 90/141 (64%) | I7: 90 | J7: 0.64 | K7: 97/44 | L7: 97 | M7: 44 | N7: 9
A8: C. Hernando | B8: LCB | C8: Center Back | D8: 79' | E8: 1205/1344 (90%) | F8: 1205 | G8: 0.9 | H8: 82/120 (68%) | I8: 82 | J8: 0.68 | K8: 133/79 | L8: 133 | M8: 79 | N8: 26
A9: D. Huckaby | B9: RB | C9: Full Back | D9: 87' | E9: 415/536 (77%) | F9: 415 | G9: 0.77 | H9: 55/94 (59%) | I9: 55 | J9: 0.59 | K9: 45/13 | L9: 45 | M9: 13 | N9: 4
A10: B. Borutskie | B10: RCB | C10: Center Back | D10: 91' | E10: 465/503 (92%) | F10: 465 | G10: 0.92 | H10: 27/43 (63%) | I10: 27 | J10: 0.63 | K10: 27/14 | L10: 27 | M10: 14 | N10: 4
A11: K. Lehnert | B11: RB | C11: Full Back | D11: 92' | E11: 334/402 (83%) | F11: 334 | G11: 0.83 | H11: 49/75 (65%) | I11: 49 | J11: 0.65 | K11: 44/21 | L11: 44 | M11: 21 | N11: 1
A12: M. Trethewey | B12: LB | C12: Full Back | D12: 97' | E12: 203/236 (86%) | F12: 203 | G12: 0.86 | H12: 26/40 (65%) | I12: 26 | J12: 0.65 | K12: 15/10 | L12: 15 | M12: 10 | N12: 1
E14: XG to Goals Conceded | H14: Goals Against Average | K14: Save Percentage %
A15: J. Lee | B15: GK | C15: Goalkeeper | D15: 104' | E15: 23.37/23 | F15: 23.37 | G15: 23 | H15: 0.96 | K15: 0.74
E17: Passes Amount & Accuracy % | H17: Loose Balls Duels Won | K17: Progressive Passes/ Accuracy % | N17: Goals | O17: Key Passes | P17: Opp Half Recoveries
A18: R. Baer | B18: RDMF | C18: Center Mid | D18: 38' | E18: 884/1108 (80%) | F18: 884 | G18: 0.8 | H18: 25/62 (40%) | I18: 25 | J18: 0.4 | K18: 109/132 (83%) | L18: 109 | M18: 0.83
A19: O. Ollikainen | B19: LDMF | C19: Center Mid | D19: 48' | E19: 803/926 (87%) | F19: 803 | G19: 0.87 | H19: 19/54 (35%) | I19: 19 | J19: 0.35 | K19: 86/119 (72%) | L19: 86 | M19: 0.72
A20: Y. Tsukada | B20: LAMF | C20: Attacking Mid | D20: 70' | E20: 505/675 (75%) | F20: 505 | G20: 0.75 | H20: 11/39 (28%) | I20: 11 | J20: 0.28 | K20: 103/121 (85%) | L20: 103 | M20: 0.85 | N20: 12 | O20: 29 | P20: 61/103 (59%)
A21: L. Mccormick | B21: AMF | C21: Attacking Mid | D21: 83' | E21: 502/663 (76%) | F21: 502 | G21: 0.76 | H21: 18/47 (38%) | I21: 18 | J21: 0.38 | K21: 73/79 (92%) | L21: 73 | M21: 0.92 | N21: 7 | O21: 10 | P21: 44/73 (60%)
A22: S. Ors | B22: RAMF | C22: Attacking Mid | D22: 87' | E22: 518/618 (84%) | F22: 518 | G22: 0.84 | H22: 18/51 (35%) | I22: 18 | J22: 0.35 | K22: 38/54 (70%) | L22: 38 | M22: 0.7 | N22: 8 | O22: 4 | P22: 58/104 (56%)
A23: K. Christou | B23: AMF | C23: Attacking Mid | D23: 96' | E23: 338/509 (66%) | F23: 338 | G23: 0.66 | H23: 21/41 (51%) | I23: 21 | J23: 0.51 | K23: 40/52 (77%) | L23: 40 | M23: 0.77 | N23: 1 | O23: 6 | P23: 39/68 (57%)

Sheet Notre Dame
A1: Player | B1: Position | C1: Position Category | D1: Average Minutes Played | E1: Position Metrics
E2: Goals to XG | H2: Key Passes | K2: Opp Half Recoveries
A3: M. Roou | B3: CF | C3: Striker | D3: 81' | E3: 10/6.95 | F3: 10 | G3: 6.95 | H3: 7 | K3: 43
A4: N. Spicer | B4: CF | C4: Striker | D4: 54' | E4: 1/1.73 | F4: 1 | G4: 1.73 | H4: 4 | K4: 38
A5: E. Nto | B5: CF | C5: Striker | D5: 51' | E5: 11/8.64 | F5: 11 | G5: 8.64 | H5: 1 | K5: 22
E7: Successful Dribbles (Amount and Successful %) | H7: Crosses (Amount and Accurate %) | K7: Key Passes/Goals | L7: kp | M7: goals | N7: Opp Half Recoveries
A8: S. Green | B8: RW | C8: Wingers | D8: 44' | E8: 18/37 (49%) | F8: 18 | G8: 0.49 | H8: 7/15 (47%) | I8: 7 | J8: 0.47 | K8: 2 (0 goals) | N8: 34
A9: K. Baffour | B9: LW | C9: Wingers | D9: 71' | E9: 46/113 (41%) | F9: 46 | G9: 0.41 | H9: 6/31 (19%) | I9: 6 | J9: 0.19 | K9: 13 (2 goals) | N9: 53
A10: D. Russo | B10: RW | C10: Wingers | D10: 79' | E10: 77/141 (55%) | F10: 77 | G10: 0.55 | H10: 8/33 (24%) | I10: 8 | J10: 0.24 | K10: 10 (4 goals) | N10: 65
E12: Total Passes and Accuracy % | H12: Defensive Duels Won % | K12: Interceptions/Clearances | L12: int | M12: clear | N12: Blocked Shots
A13: J. Ramsey | B13: LCB | C13: Center Back | D13: 100' | E13: 775/947 (82%) | F13: 775 | G13: 0.82 | H13: 92/136 (68%) | I13: 92 | J13: 0.68 | K13: 95/88 | L13: 95 | M13: 88 | N13: 16
A14: M. Ferguson | B14: RCB | C14: Center Back | D14: 83' | E14: 707/852 (83%) | F14: 707 | G14: 0.83 | H14: 44/58 (76%) | I14: 44 | J14: 0.76 | K14: 82/55 | L14: 82 | M14: 55 | N14: 15
A15: M. Williams | B15: RCB | C15: Center Back | D15: 64' | E15: 300/355 (85%) | F15: 300 | G15: 0.85 | H15: 33/48 (69%) | I15: 33 | J15: 0.69 | K15: 60/40 | L15: 60 | M15: 40 | N15: 8
A17: K. Genenbacher | B17: RB | C17: Fullback | D17: 103' | E17: 801/967 (83%) | F17: 801 | G17: 0.83 | H17: 90/142 (63%) | I17: 90 | J17: 0.63 | K17: 133/46 | L17: 133 | M17: 46 | N17: 22
A18: P. Burns | B18: LB | C18: Fullback | D18: 93' | E18: 517/772 (67%) | F18: 517 | G18: 0.67 | H18: 97/145 (67%) | I18: 97 | J18: 0.67 | K18: 112/56 | L18: 112 | M18: 56 | N18: 8
A20: B. Dowd | B20: GK | C20: Goalkeeper | D20: 104' | E20: 24.68/15 | F20: 24.68 | G20: 15 | H20: 0.68 | K20: 0.83
E22: Passes Amount & Accuracy % | H22: Loose Balls Duels Won | K22: Progressive Passes/ Accuracy % | L22: pps | M22: %
A23: B. Boneau | B23: RCMF | C23: Center Mid | D23: 96' | E23: 773/883 (88%) | F23: 773 | G23: 0.88 | H23: 19/44 (43%) | I23: 19 | J23: 0.43 | K23: 113/140 (81%) | L23: 113 | M23: 0.81
A24: E. O'Brien | B24: LCMF | C24: Center Mid | D24: 80' | E24: 512/597 (86%) | F24: 512 | G24: 0.86 | H24: 17/39 (44%) | I24: 17 | J24: 0.44 | K24: 44/68 (65%) | L24: 44 | M24: 0.65
A25: W. Lewis | B25: LCMF | C25: Center Mid | D25: 52' | E25: 405/487 (83%) | F25: 405 | G25: 0.83 | H25: 23/47 (49%) | I25: 23 | J25: 0.49 | K25: 45/64 (70%) | L25: 45 | M25: 0.7
C29: =COUNTIF($C$2:$C$26,"Center Back") -> 3

Sheet Stanford
A1: Player | B1: Position | C1: Positon Category | D1: Average Minutes Played | E1: Position Metrics
E2: Goals to XG | F2: goal | G2: xg | H2: Key Passes | K2: Opp Half Recoveries
A3: S. de Flores | B3: CF | C3: Attacker | D3: 74' | E3: 7/5.71 | F3: 7 | G3: 5.71 | H3: 8 | K3: 31/42 (74%)
A4: J. Kiil | B4: CF | C4: Attacker | D4: 74' | E4: 7/4.01 | F4: 7 | G4: 4.01 | H4: 3 | K4: 27/43 (63%)
A5: D. Jarvie | B5: CF | C5: Attacker | D5: 30' | E5: 2/1.37 | F5: 2 | G5: 1.37 | H5: 1 | K5: 7/8 (88%)
A6: A. Tenconi-Gradillas | B6: CF | C6: Attacker | D6: 29' | E6: 1/1.42 | F6: 1 | G6: 1.42 | H6: 4 | K6: 11/14 (79%)
E8: Successful Dribbles (Amount and Successful %) | F8: amnt | G8: % | H8: Crosses (Amount and Accurate %) | I8: amnt | J8: % | K8: Key Passes/Goals | L8: kp | M8: goal | N8: Opp Half Recoveries
A9: Z. Bohane | B9: RW | C9: Wingers | D9: 93' | E9: 33/51 (65%) | F9: 33 | G9: 0.65 | H9: 9/28 (32%) | I9: 9 | J9: 0.32 | K9: 45419 | L9: 5 | M9: 7 | N9: 89/152 (59%)
A10: F. Bank | B10: LW | C10: Wingers | D10: 88' | E10: 67/99 (68%) | F10: 67 | G10: 0.68 | H10: 46/115 (40%) | I10: 46 | J10: 0.4 | K10: 17/3 | L10: 17 | M10: 3 | N10: 67/105 (64%)
E12: Total Passes and Accuracy % | F12: amnt | G12: % | H12: Defensive Duels Won % | I12: amnt | J12: 5 | K12: Interceptions/Clearances | L12: int | M12: clear | N12: Blocked Shots
A13: N. Adnan | B13: RCB | C13: Center Back | D13: 104' | E13: 535/658 (81%) | F13: 535 | G13: 0.81 | H13: 101/152 (66%) | I13: 101 | J13: 0.66 | K13: 99/72 | L13: 99 | M13: 72 | N13: 19
A14: P. Bank | B14: LB | C14: Fullback | D14: 88' | E14: 538/730 (74%) | F14: 538 | G14: 0.74 | H14: 101/148 (68%) | I14: 101 | J14: 0.68 | K14: 91/41 | L14: 91 | M14: 41 | N14: 4
A15: D. Hooper | B15: LCB | C15: Center Back | D15: 99' | E15: 591/759 (78%) | F15: 591 | G15: 0.78 | H15: 57/93 (61%) | I15: 57 | J15: 0.61 | K15: 100/56 | L15: 100 | M15: 56 | N15: 11
A16: R. Dunn | B16: RB | C16: Fullback | D16: 82' | E16: 340/452 (75%) | F16: 340 | G16: 0.75 | H16: 77/118 (65%) | I16: 77 | J16: 0.65 | K16: 85/54 | L16: 85 | M16: 54 | N16: 9
A17: W. Cleary | B17: RB | C17: Fullback | D17: 60' | E17: 336/494 (68%) | F17: 336 | G17: 0.68 | H17: 66/97 (68%) | I17: 66 | J17: 0.68 | K17: 64/37 | L17: 64 | M17: 37 | N17: 2
E19: XG to Goals Conceded | F19: xg | G19: conceded | H19: Goals Against Average | K19: Save Percentage %
A20: R. Schnebly | B20: GK | C20: Goalkeeper | D20: 103' | E20: 18.91/19 | F20: 18.91 | G20: 19 | H20: 0.95 | K20: 0.7
E22: Passes Amount & Accuracy % | F22: amnt | G22: % | H22: Loose Balls Duels Won | I22: amnt | J22: % | K22: Progressive Passes/ Accuracy % | L22: pps | M22: %
A23: M. Fisher | B23: RCMF | C23: Midfielder | D23: 101' | E23: 525/652 (81%) | F23: 525 | G23: 0.81 | H23: 27/69 (39%) | I23: 27 | J23: 0.39 | K23: 101/130 (78%) | L23: 101 | M23: 0.78
A24: W. Reilly | B24: LCMF | C24: Midfielder | D24: 88' | E24: 430/546 (79%) | F24: 430 | G24: 0.79 | H24: 33/72 (46%) | I24: 33 | J24: 0.46 | K24: 89/116 (77%) | L24: 89 | M24: 0.77
A25: L. Purchase | B25: RCMF | C25: Midfielder | D25: 42' | E25: 141/209 (67%) | F25: 141 | G25: 0.67 | H25: 12/31 (39%) | I25: 12 | J25: 0.39 | K25: 17/35 (49%) | L25: 17 | M25: 0.49
C28: =COUNTIF($C$2:$C$26,"Center Back") -> 2

Sheet UNC
A1: Player | B1: Position | C1: Position Category | D1: Average Minutes Played | E1: Position Metrics
E2: Goals to XG | F2: goal | G2: xg | H2: Key Passes | K2: Opp Half Recoveries
A3: M. Vician | B3: CF | C3: Striker | D3: 82' | E3: 10/9.13 | F3: 10 | G3: 9.13 | H3: 9 | K3: 32/53 (60%)
E5: Successful Dribbles (Amount and Successful %) | F5: amnt | G5: % | H5: Crosses (Amount and Accurate %) | I5: amnt | J5: % | K5: Key Passes/Goals | L5: kp | M5: goal | N5: Opp Half Recoveries
A6: Q. Huerman | B6: RWF | C6: Wingers | D6: 86' | E6: 57/107 (53%) | F6: 57 | G6: 0.53 | H6: 11/34 (32%) | I6: 11 | J6: 0.32 | K6: 19 / 10 Goals | L6: 19 | M6: 10 | N6: 61
A7: A. Al-Qaq | B7: LWF | C7: Wingers | D7: 59' | E7: 75/145 (52%) | F7: 75 | G7: 0.52 | H7: 11/56 (20%) | I7: 11 | J7: 0.2 | K7: 10 / 4 Goals | L7: 10 | M7: 4 | N7: 35
A8: E. Bawa | B8: LWF | C8: Wingers | D8: 34' | E8: 35/61 (57%) | F8: 35 | G8: 0.57 | H8: 1/6 (17%) | I8: 1 | J8: 0.17 | K8: 4 / 4 Goals | L8: 4 | M8: 4 | N8: 19
A9: D. Bercedo | B9: LWF | C9: Wingers | D9: 50' | E9: 25/56 (45%) | F9: 25 | G9: 0.45 | H9: 1/16 (6%) | I9: 1 | J9: 0.06 | K9: 9 / 1 Goals | L9: 9 | M9: 1 | N9: 35
E10: =AVERAGE(N12:N16) -> 4.8
E11: Total Passes and Accuracy % | F11: amnt | G11: % | H11: Defensive Duels Won % | I11: amnt | J11: % | K11: Interceptions/Clearances | L11: int | M11: clear | N11: Blocked Shots
A12: T. Zinnhardt | B12: RCB | C12: Center Back | D12: 107' | E12: 836/983 (85%) | F12: 836 | G12: 0.85 | H12: 110/150 (73%) | I12: 110 | J12: 0.73 | K12: 124/64 | L12: 124 | M12: 64 | N12: 11
A13: R. Thomas | B13: RB | C13: Fullback | D13: 100' | E13: 715/919 (78%) | F13: 715 | G13: 0.78 | H13: 92/140 (66%) | I13: 92 | J13: 0.66 | K13: 102/60 | L13: 102 | M13: 60 | N13: 5
A14: C. Harper | B14: LCB | C14: Center Back | D14: 105' | E14: 832/939 (89%) | F14: 832 | G14: 0.89 | H14: 78/100 (78%) | I14: 78 | J14: 0.78 | K14: 106/71 | L14: 106 | M14: 71 | N14: 4
A15: M. Edwards | B15: RB | C15: Fullback | D15: 97' | E15: 753/879 (86%) | F15: 753 | G15: 0.86 | H15: 72/119 (61%) | I15: 72 | J15: 0.61 | K15: 91/42 | L15: 91 | M15: 42 | N15: 2
A16: V. Hole Vik | B16: RB | C16: Fullback | D16: 42' | E16: 227/272 (83%) | F16: 227 | G16: 0.83 | H16: 35/58 (60%) | I16: 35 | J16: 0.6 | K16: 27/13 | L16: 27 | M16: 13 | N16: 2
E17: XG to Goals Conceded | F17: xg | G17: conceded | H17: Goals Against Average | K17: Save Percentage %
A18: A. Cordes | B18: GK | C18: Goalkeeper | D18: 105' | E18: 23.41/15 | F18: 23.41 | G18: 15 | H18: 0.68 | K18: 0.85
E20: Passes Amount & Accuracy % | F20: amnt | G20: % | H20: Loose Balls Duels Won | I20: amnt | J20: % | K20: Progressive Passes/ Accuracy % | L20: pps | M20: %
A21: A. Czech | B21: RCMF | C21: Midfielder | D21: 101' | E21: 564/755 (75%) | F21: 564 | G21: 0.75 | H21: 34/80 (43%) | I21: 34 | J21: 0.43 | K21: 64/115 (56%) | L21: 64 | M21: 0.56
A22: S. Williams | B22: DMF | C22: Midfielder | D22: 103' | E22: 931/1054 (88%) | F22: 931 | G22: 0.88 | H22: 42/89 (47%) | I22: 42 | J22: 0.47 | K22: 97/123 (79%) | L22: 97 | M22: 0.79
A23: P. O'Ferral | B23: LCMF | C23: Midfielder | D23: 81' | E23: 513/690 (74%) | F23: 513 | G23: 0.74 | H23: 22/44 (50%) | I23: 22 | J23: 0.5 | K23: 92/121 (76%) | L23: 92 | M23: 0.76
A24: J. Charles | B24: LCMF | C24: Midfielder | D24: 32' | E24: 242/295 (82%) | F24: 242 | G24: 0.82 | H24: 5/19 (26%) | I24: 5 | J24: 0.26 | K24: 35/52 (67%) | L24: 35 | M24: 0.67
C27: =COUNTIF($C$2:$C$26,"Center Back") -> 2

Sheet LMU
A1: Position | B1: Position Category | C1: Average Minutes Played | D1: Position Metrics
D2: Goals to XG | E2: Goals | F2: xg | G2: Key Passes | N2: Opp Half Recoveries
A3: CF | B3: Strikers | C3: 95' | D3: 6/6.69 | E3: 6 | F3: 6.69 | G3: 7 | N3: 39
A4: CF | B4: Strikers | C4: 78' | D4: 6/5.74 | E4: 6 | F4: 5.74 | G4: 5 | N4: 27
A5: CF | B5: Strikers | C5: 61' | D5: 0/2.1 | E5: 0 | F5: 2.1 | G5: 3 | N5: 23
A6: CF | B6: Strikers | C6: 64' | D6: 0/.57 | E6: 0 | F6: 0.57 | G6: 2 | N6: 11
B8: =AVERAGE(6,14,11,2) -> 8.25 | C8: =AVERAGE(65,53,50,25) -> 48.25 | D8: Total Passes and Accuracy % | E8: amnt | F8: % | G8: Defensive Duels Won % | J8: amnt | M8: % | N8: Interceptions/Clearances | O8: int | P8: clear | Q8: Blocked Shots
A9: CB | B9: Center Back | C9: 98' | D9: 462/541 (85%) | E9: 463 | F9: 0.85 | G9: 50/73 (68%) | J9: 50 | M9: 0.68 | N9: 74/65 | O9: 74 | P9: 65 | Q9: 6
A10: RCB | B10: Center Back | C10: 91' | D10: 474/598 (79%) | E10: 474 | F10: 0.79 | G10: 89/145 (61%) | J10: 89 | M10: 0.61 | N10: 74/53 | O10: 74 | P10: 53 | Q10: 14
A11: LCB | B11: Center Back | C11: 95' | D11: 661/805 (82%) | E11: 661 | F11: 0.82 | G11: 95/135 (70%) | J11: 95 | M11: 0.7 | N11: 107/50 | O11: 107 | P11: 50 | Q11: 11
A12: LB | B12: Fullback | C12: 75' | D12: 321/447 (72%) | E12: 321 | F12: 0.72 | G12: 86/151 (57%) | J12: 86 | M12: 0.57 | N12: 71/25 | O12: 71 | P12: 25 | Q12: 2
D14: XG to Goals Conceded | E14: xg | F14: conceded | G14: Goals Against Average | N14: Save Percentage %
A15: GK | B15: Goalkeeper | C15: 103' | D15: 25.29/21 | E15: 25.29 | F15: 21 | G15: 1.05 | N15: 0.78
D17: Passes Amount & Accuracy % | E17: amnt | F17: % | G17: Loose Balls Duels Won | J17: amnt | M17: % | N17: Progressive Passes/ Accuracy % | O17: pps | P17: %
A18: LCMF | B18: Center Mid | C18: 92' | D18: 398/490 (81%) | E18: 398 | F18: 0.81 | G18: 9/42 (21%) | J18: 9 | M18: 0.21 | N18: 75/123 (61%) | O18: 75 | P18: 0.61
A19: RCMF | B19: Center Mid | C19: 29' | D19: 86/126 (68%) | E19: 86 | F19: 0.68 | G19: 7/14 (50%) | J19: 7 | M19: 0.5 | N19: 11/24 (46%) | O19: 11 | P19: 0.46
A20: RCMF | B20: Center Mid | C20: 86' | D20: 452/530 (85%) | E20: 452 | F20: 0.85 | G20: 16/36 (44%) | J20: 16 | M20: 0.44 | N20: 41/72 (57%) | O20: 41 | P20: 0.57
A21: LCMF | B21: Center Mid | C21: 64' | D21: 342/426 (80%) | E21: 342 | F21: 0.8 | G21: 14/30 (47%) | J21: 14 | M21: 0.47 | N21: 54/92 (59%) | O21: 54 | P21: 0.59
D23: Successful Dribbles (Amount and Successful %) | E23: amnt | F23: % | G23: Crosses (Amount and Accurate %) | H23: amnt | I23: % | J23: Key Passes/Goals | K23: Key Passes | L23: Goals | M23: Opp Half Recoveries
A24: LWB | B24: Wingers | C24: 88' | D24: 26/35 (74%) | E24: 26 | F24: 0.74 | G24: 10/49 (20%) | H24: 10 | I24: 0.2 | J24: 5/2 Goals | K24: 5 | L24: 2 | M24: 37
A25: RWB | B25: Wingers | C25: 73' | D25: 23/40 (58%) | E25: 23 | F25: 0.58 | G25: 12/34 (35%) | H25: 12 | I25: 0.35 | J25: 4/ 0 Goals | K25: 4 | L25: 0 | M25: 21
C29: =COUNTIF($B$2:$B$26,"Center Back") -> 3

Sheet Indiana
A1: Position | B1: Position Category | C1: Average Minutes Played | D1: Position Metrics
D2: Goals to XG | E2: Goals | F2: xg | G2: Key Passes | J2: Opp Half Recoveries
B3: Strikers | C3: 80' | D3: 5/3.87 | E3: 5 | F3: 3.87 | G3: 6 | J3: 43/88 (49%)
B4: Strikers | C4: 92' | D4: 8/6.77 | E4: 8 | F4: 6.77 | G4: 25 | J4: 62/94 (66%)
B5: Strikers | C5: 49' | D5: 4/6.88 | E5: 4 | F5: 6.88 | G5: 10 | J5: 32/49 (65%)
B6: Strikers | C6: 11' | D6: 0/1.02 | E6: 0 | F6: 1.02 | G6: 0 | J6: 4/7 (57%)
D8: Successful Dribbles (Amount and Successful %) | E8: amnt | F8: % | G8: Crosses (Amount and Accurate %) | H8: amnt | I8: % | J8: Key Passes/Goals | K8: KP | L8: Goals | M8: Opp Half Recoveries
B9: Wingers | C9: 80' | D9: 75/140 (54%) | E9: 75 | F9: 0.54 | G9: 16/54 (30%) | H9: 16 | I9: 0.3 | J9: 45475 | K9: 7 | L9: 2 | M9: 54/92 (59%)
B10: Wingers | C10: 81' | D10: 79/131 (60%) | E10: 79 | F10: 0.6 | G10: 21/60 (35%) | H10: 21 | I10: 0.35 | J10: 17/5 | K10: 17 | L10: 5 | M10: 82/139 (59%)
B11: Wingers | C11: 17' | D11: 14/30 (47%) | E11: 14 | F11: 0.47 | G11: 7/19 (37%) | H11: 7 | I11: 0.37 | J11: 1/0 | K11: 1 | L11: 0 | M11: 15/23(56%)
D13: Total Passes and Accuracy % | E13: amnt | F13: % | G13: Defensive Duels Won % | H13: amnt | I13: % | J13: Interceptions/Clearances | K13: Int | L13: Clear | M13: Blocked Shots
A14: FB | B14: Fullback | C14: 101' | D14: 715/995 (72%) | E14: 715 | F14: 0.72 | G14: 133/219 (61%) | H14: 133 | I14: 0.61 | J14: 100/61 | K14: 100 | L14: 61 | M14: 3
A15: CB | B15: Center Back | C15: 100' | D15: 956/1123 (85%) | E15: 956 | F15: 0.98 | G15: 59/100 (59%) | H15: 59 | I15: 0.59 | J15: 103/96 | K15: 103 | L15: 96 | M15: 11
A16: CB | B16: Center Back | C16: 95' | D16: 614/758 (81%) | E16: 614 | F16: 0.81 | G16: 96/139 (69%) | H16: 96 | I16: 0.69 | J16: 109/69 | K16: 109 | L16: 69 | M16: 12
A17: FB | B17: Fullback | C17: 96' | D17: 603/702 (86%) | E17: 603 | F17: 0.86 | G17: 85/133 (64%) | H17: 85 | I17: 0.64 | J17: 83/35 | K17: 83 | L17: 35 | M17: 5
D19: XG to Goals Conceded | E19: xg | F19: conceded | G19: Goals Against Average | J19: Save Percentage %
B20: Goalkeeper | C20: 104' | D20: 19/18 | E20: 19 | F20: 18 | G20: 0.79 | J20: 0.74
D22: Passes Amount & Accuracy % | E22: amnt | F22: % | G22: Loose Balls Duels Won | H22: amnt | I22: % | J22: Progressive Passes/ Accuracy % | K22: pps | L22: %
A23: CM | B23: Center Mid | C23: 98' | D23: 712/883 (81%) | E23: 712 | F23: 0.81 | G23: 59/120 (49%) | H23: 59 | I23: 0.49 | J23: 148/194 (76%) | K23: 148 | L23: 0.76
A24: CM | B24: Center Mid | C24: 103' | D24: 868/1091 (80%) | E24: 868 | F24: 0.8 | G24: 31/63 (49%) | H24: 31 | I24: 0.49 | J24: 133/176 (76%) | K24: 133 | L24: 0.76
A25: CM | B25: Center Mid | C25: 48' | D25: 360/440 (82%) | E25: 360 | F25: 0.82 | G25: 16/38 (42%) | H25: 16 | I25: 0.42 | J25: 53/68 (78%) | K25: 53 | L25: 0.78
B28: =COUNTIF($B$2:$B$26,"Center Back") -> 2

Sheet UNCC
A1: Player | B1: Position | C1: Position Category | D1: Average Minutes Played | E1: Position Metrics
E2: Goals to XG | F2: Goals | G2: xg | H2: Key Passes | K2: Opp Half Recoveries
A3: B. Larsen | B3: CF | C3: Striker | D3: 73' | E3: 4/5.35 | F3: 4 | G3: 5.35 | H3: 4 | K3: 29/42 (69%)
A4: F. Jauk | B4: CF | C4: Striker | D4: 40' | E4: 3/4.38 | F4: 3 | G4: 4.38 | H4: 2 | K4: 11/17 (65%)
E6: Successful Dribbles (Amount and Successful %) | F6: Amnt | G6: % | H6: Crosses (Amount and Accurate %) | I6: amnt | J6: % | K6: Key Passes/Goals | L6: KP | M6: goals | N6: Opp Half Recoveries
A7: J. Nyandjo | B7: RW | C7: Wingers | D7: 81' | E7: 73/138 (53%) | F7: 73 | G7: 0.53 | H7: 16/46 (35%) | I7: 16 | J7: 0.35 | K7: 32 / 4 Goals | L7: 32 | M7: 4 | N7: 44
A8: B. Morales | B8: LW | C8: Wingers | D8: 74' | E8: 28/51 (55%) | F8: 28 | G8: 0.55 | H8: 12/30 (40%) | I8: 12 | J8: 0.4 | K8: 22 / 4 Goals | L8: 22 | M8: 4 | N8: 36
A9: B. Dildy | B9: LW | C9: Wingers | D9: 39' | E9: 10/23 (43%) | F9: 10 | G9: 0.43 | H9: 17/39 (44%) | I9: 17 | J9: 0.44 | K9: 10 / 1 Goals | L9: 10 | M9: 1 | N9: 23
A10: L. Frost | B10: RW | C10: Wingers | D10: 37' | E10: 8/22 (36%) | F10: 8 | G10: 0.36 | H10: 1/12 (8%) | I10: 1 | J10: 0.8 | K10: 5 / 0 Goals | L10: 5 | M10: 0 | N10: 16
E12: Total Passes and Accuracy % | F12: amnt | G12: % | H12: Defensive Duels Won % | I12: amnt | J12: % | K12: Interceptions/Clearances | L12: Int | M12: Clear | N12: Blocked Shots
A13: I. Pilcher | B13: LCB | C13: Center Back | D13: 101' | E13: 652/803 (81%) | F13: 652 | G13: 0.81 | H13: 74/116 (64%) | I13: 74 | J13: 0.64 | K13: 101/52 | L13: 101 | M13: 52 | N13: 13
A14: L. Laursen | B14: RCB | C14: Center Back | D14: 101' | E14: 569/690 (82%) | F14: 569 | G14: 0.82 | H14: 49/70 (70%) | I14: 49 | J14: 0.7 | K14: 87/34 | L14: 87 | M14: 34 | N14: 4
F16: amnt | G16: % | I16: amnt | J16: %
A17: D. Moore | B17: LB | C17: Full Back | D17: 85' | E17: 385/520 (74%) | F17: 385 | G17: 0.74 | H17: 87/132 (66%) | I17: 87 | J17: 0.66 | K17: 78/26 | N17: 4
A18: A. Fofana | B18: RB | C18: Full Back | D18: 60' | E18: 287/370 (78%) | F18: 287 | G18: 0.78 | H18: 48/71 (68%) | I18: 48 | J18: 0.68 | K18: 61/31 | N18: 3
E20: XG to Goals Conceded | F20: xg | G20: conceded | H20: Goals Against Average | K20: Save Percentage %
A21: L. Stritter | B21: GK | C21: Goalkeepers | D21: 101' | E21: 16.4/15 | F21: 16.4 | G21: 15 | H21: 0.88 | K21: 0.73
E23: Passes Amount & Accuracy % | F23: amnt | G23: % | H23: Loose Balls Duels Won | I23: amnt | J23: % | K23: Progressive Passes/ Accuracy % | L23: pps | M23: %
A24: R. Tori | B24: RCMF | C24: Center Midfielder | D24: 86' | E24: 535/738 (72%) | F24: 535 | G24: 0.72 | H24: 23/57 (40%) | I24: 23 | J24: 0.4 | K24: 88/117 (75%) | L24: 88 | M24: 0.75
A25: M. Kirk | B25: LCMF | C25: Center Midfielder | D25: 76' | E25: 525/686 (77%) | F25: 525 | G25: 0.77 | H25: 23/43 (53%) | I25: 23 | J25: 0.53 | K25: 70/101 (69%) | L25: 70 | M25: 0.69
A26: S. Kolby | B26: LDMF | C26: Center Midfielder | D26: 48' | E26: 242/320 (76%) | F26: 242 | G26: 0.76 | H26: 9/31 (29%) | I26: 9 | J26: 0.29 | K26: 39/51 (76%) | L26: 39 | M26: 0.76
A27: L. Husakiwsky | B27: LCMF | C27: Center Midfielder | D27: 38' | E27: 203/257 (79%) | F27: 203 | G27: 0.79 | H27: 10/18 (56%) | I27: 10 | J27: 0.56 | K27: 35/43 (81%) | L27: 35 | M27: 0.81
C31: =COUNTIF($C$2:$C$26,"Center Back") -> 2

Sheet Save %
A1: Clemson | D1: Oregon State | G1: WVU | J1: Notre Dame | M1: Stanford | P1: UNC | S1: LMU | V1: Indiana | Y1: UNCC
A2: Saves | B2: Shots Against | D2: Saves | E2: Shots Against | G2: Saves | H2: Shots Against | J2: Saves | K2: Shots Against | M2: Saves | N2: Shots Against | P2: Saves | Q2: Shots Against | S2: Saves | T2: Shots Against | V2: Saves | W2: Shots Against | Y2: Saves | Z2: Shots Against
A3: 1 | B3: 3 | D3: 4 | E3: 6 | G3: 5 | H3: 5 | J3: 4 | K3: 5 | M3: 3 | N3: 4 | P3: 2 | Q3: 3 | S3: 2 | T3: 3 | V3: 1 | W3: 2 | Y3: 1 | Z3: 1
A4: 2 | B4: 3 | D4: 2 | E4: 2 | G4: 1 | H4: 1 | J4: 2 | K4: 2 | M4: 2 | N4: 3 | P4: 1 | Q4: 2 | S4: 3 | T4: 4 | V4: 1 | W4: 2 | Y4: 0 | Z4: 2
A5: 1 | B5: 1 | D5: 1 | E5: 2 | G5: 0 | H5: 0 | J5: 1 | K5: 1 | M5: 0 | N5: 0 | P5: 2 | Q5: 3 | S5: 1 | T5: 3 | V5: 2 | W5: 3 | Y5: 1 | Z5: 3
A6: 5 | B6: 8 | D6: 4 | E6: 5 | G6: 4 | H6: 5 | J6: 1 | K6: 1 | M6: 3 | N6: 4 | P6: 1 | Q6: 2 | S6: 3 | T6: 4 | V6: 2 | W6: 2 | Y6: 0 | Z6: 0
A7: 0 | B7: 2 | D7: 1 | E7: 3 | G7: 1 | H7: 1 | J7: 4 | K7: 6 | M7: 1 | N7: 2 | P7: 0 | Q7: 1 | S7: 2 | T7: 3 | V7: 5 | W7: 6 | Y7: 2 | Z7: 2
A8: 5 | B8: 5 | D8: 0 | E8: 0 | G8: 4 | H8: 6 | J8: 1 | K8: 2 | M8: 3 | N8: 5 | P8: 1 | Q8: 1 | S8: 3 | T8: 5 | V8: 1 | W8: 1 | Y8: 3 | Z8: 3
A9: 1 | B9: 1 | D9: 3 | E9: 4 | G9: 3 | H9: 3 | J9: 4 | K9: 5 | M9: 0 | N9: 0 | P9: 3 | Q9: 4 | S9: 3 | T9: 3 | V9: 1 | W9: 1 | Y9: 1 | Z9: 2
A10: 2 | B10: 3 | D10: 1 | E10: 1 | G10: 0 | H10: 0 | J10: 11 | K10: 11 | M10: 3 | N10: 5 | P10: 4 | Q10: 4 | S10: 7 | T10: 8 | V10: 2 | W10: 4 | Y10: 3 | Z10: 4
A11: 8 | B11: 9 | D11: 6 | E11: 8 | G11: 5 | H11: 6 | J11: 5 | K11: 6 | M11: 1 | N11: 1 | P11: 3 | Q11: 3 | S11: 3 | T11: 3 | V11: 3 | W11: 3 | Y11: 5 | Z11: 6
A12: 0 | B12: 1 | D12: 3 | E12: 5 | G12: 2 | H12: 5 | J12: 2 | K12: 3 | M12: 1 | N12: 1 | P12: 3 | Q12: 4 | S12: 4 | T12: 5 | V12: 4 | W12: 5 | Y12: 3 | Z12: 4
A13: 1 | B13: 1 | D13: 1 | E13: 3 | G13: 1 | H13: 2 | J13: 6 | K13: 6 | M13: 5 | N13: 7 | P13: 4 | Q13: 4 | S13: 3 | T13: 3 | V13: 2 | W13: 3 | Y13: 3 | Z13: 4
A14: 3 | B14: 4 | D14: 1 | E14: 5 | G14: 6 | H14: 8 | J14: 1 | K14: 1 | M14: 2 | N14: 2 | P14: 6 | Q14: 7 | S14: 1 | T14: 3 | V14: 0 | W14: 0 | Y14: 3 | Z14: 3
... A20: 1 | B20: 1 | D20: 2 | E20: 2 | G20: 2 | H20: 3 | J20: 3 | K20: 3 | M20: 4 | N20: 5 | P20: 7 | Q20: 8 | S20: 9 | T20: 9 | V20: 4 | W20: 5 | Y20: 1 | Z20: 4
A21: 2 | B21: 2 | D21: 2 | E21: 3 | G21: 3 | H21: 3 | J21: 7 | K21: 7 | M21: 2 | N21: 2 | P21: 3 | Q21: 4 | S21: 8 | T21: 8 | V21: 5 | W21: 8
A22: 2 | B22: 2 | D22: 1 | E22: 1 | G22: 4 | H22: 7 | J22: 4 | K22: 5 | M22: 5 | N22: 7 | P22: 0 | Q22: 0 | S22: 3 | T22: 6 | V22: 2 | W22: 2 | Y22: Sum | Z22: Sum
A23: 3 | B23: 3 | D23: 3 | E23: 4 | G23: 3 | H23: 3 | J23: 5 | K23: 5 | P23: 4 | Q23: 6 | V23: 3 | W23: 4 | Y23: =SUM(Y5:Y20) -> 37 | Z23: =SUM(Z5:Z20) -> 51
A24: 3 | B24: 4 | G24: 4 | H24: 5 | J24: 2 | K24: 4 | M24: Sum | N24: Sum | P24: 5 | Q24: 6 | S24: Sum | T24: Sum | V24: 5 | W24: 7
G25: 5 | H25: 6 | M25: =SUM(M10:M22) -> 30 | N25: =SUM(N10:N22) -> 43 | S25: =SUM(S3:S22)-5 -> 73 | T25: =SUM(T3:T22)-6 -> 93 | V25: 4 | W25: 4 | Y25: Save Percentage | Z25: =Y23/Z23 -> 0.7254902
A26: Average | B26: Average | D26: Sum | E26: Sum | G26: 4 | H26: 5 | J26: Sum | K26: Sum | P26: Sum | Q26: Sum | V26: 2 | W26: 3
A27: =AVERAGE(A3:A24) -> 2.5 | B27: =AVERAGE(B3:B24) -> 3.3636364 | D27: =SUM(D9:D23) -> 32 | E27: =SUM(E9:E23) -> 48 | J27: =SUM(J3:J24)-1 -> 71 | K27: =SUM(K3:K24)-1 -> 86 | M27: Save Percentage | N27: =M25/N25 -> 0.69767442 | P27: =SUM(P8:P24) -> 56 | Q27: =SUM(Q8:Q24) -> 66 | S27: Save Percentage | T27: =S25/T25 -> 0.78494624
G28: Sum | H28: Sum | V28: Sum | W28: Sum
A29: Sum | B29: Sum | D29: Save Percentage | E29: =D27/E27 -> 0.66666667 | G29: =SUM(G3:G26) -> 67 | H29: =SUM(H3:H26) -> 90 | J29: Save Percentage | K29: =J27/K27 -> 0.8255814 | P29: Save Percentage | Q29: =P27/Q27 -> 0.84848485 | V29: =SUM(V3:V26) -> 57 | W29: =SUM(W3:W26) -> 77
A30: =SUM(A3:A24) -> 55 | B30: =SUM(B3:B24) -> 74
G31: Save Percentage | H31: =G29/H29 -> 0.74444444 | V31: Save Percentage | W31: =V29/W29 -> 0.74025974
A32: Save Percentage | B32: =A27/B27 -> 0.74324324
B33: =A30/B30 -> 0.74324324
